Workbook

Sheet Summary
A1: Road to Worlds — Implemented Card Catalog
A2: Live catalog inventory from data/cards.json (schema v2), verified 2026-07-18
A4: Catalog KPI | B4: Count | D4: Card Type | E4: Count | G4: Rarity | H4: Count
A5: Total cards | B5: =COUNTA(Cards!$B$5:$B$92) -> 88 | D5: Ingredient | E5: =COUNTIF(Cards!$E$5:$E$92,D5) -> 36 | G5: Common | H5: =COUNTIF(Cards!$H$5:$H$92,G5) -> 35
A6: Used in a starter deck | B6: =COUNTIF(Cards!$S$5:$S$92,">0") -> 50 | D6: Meal | E6: =COUNTIF(Cards!$E$5:$E$92,D6) -> 28 | G6: Uncommon | H6: =COUNTIF(Cards!$H$5:$H$92,G6) -> 17
A7: Not currently in a starter deck | B7: =B5-B6 -> 38 | D7: Tool | E7: =COUNTIF(Cards!$E$5:$E$92,D7) -> 14 | G7: Rare | H7: =COUNTIF(Cards!$H$5:$H$92,G7) -> 32
D8: Spice | E8: =COUNTIF(Cards!$E$5:$E$92,D8) -> 3 | G8: Mythic | H8: =COUNTIF(Cards!$H$5:$H$92,G8) -> 4
D9: Environment | E9: =COUNTIF(Cards!$E$5:$E$92,D9) -> 3
D10: Chef | E10: =COUNTIF(Cards!$E$5:$E$92,D10) -> 4
A12: Archetype | B12: Count | D12: Starter Deck | E12: Total Cards
A13: Spicy | B13: =COUNTIF(Cards!$F$5:$F$92,A13) -> 18 | D13: Spicy Starter | E13: =SUMIF('Starter Decks'!$B$5:$B$79,D13,'Starter Decks'!$G$5:$G$79) -> 30
A14: Hearty | B14: =COUNTIF(Cards!$F$5:$F$92,A14) -> 18 | D14: Hearty Starter | E14: =SUMIF('Starter Decks'!$B$5:$B$79,D14,'Starter Decks'!$G$5:$G$79) -> 30
A15: Sweet | B15: =COUNTIF(Cards!$F$5:$F$92,A15) -> 19 | D15: Sweet Starter | E15: =SUMIF('Starter Decks'!$B$5:$B$79,D15,'Starter Decks'!$G$5:$G$79) -> 30
A16: Fresh | B16: =COUNTIF(Cards!$F$5:$F$92,A16) -> 7 | D16: Fresh Starter | E16: =SUMIF('Starter Decks'!$B$5:$B$79,D16,'Starter Decks'!$G$5:$G$79) -> 30
A17: Funky | B17: =COUNTIF(Cards!$F$5:$F$92,A17) -> 8 | D17: Funky Starter | E17: =SUMIF('Starter Decks'!$B$5:$B$79,D17,'Starter Decks'!$G$5:$G$79) -> 30
A18: Neutral | B18: =COUNTIF(Cards!$F$5:$F$92,A18) -> 18
D20: Implementation note
D21: Cards are included when present in the live catalog loaded by ContentCatalog.gd. Campaign rarity and runtime cost are calculated using the same rules as the game code.

Sheet Cards
A1: Currently Implemented Cards
A2: Filter by type, archetype, rarity, or starter-deck usage. Runtime Cost and Campaign Rarity mirror ContentCatalog.gd.
A4: # | B4: Card ID | C4: Name | D4: Subtitle | E4: Card Type | F4: Archetype | G4: Rare Flag | H4: Campaign Rarity | I4: Attack | J4: Health | K4: Recipe / Ingredient Types | L4: Recipe Cost | M4: Discard Cost | N4: Runtime Cost | O4: Keywords | P4: Rules Text | Q4: Implementation Hooks | R4: Starter Decks | S4: Starter Copies | T4: Source
A5: 1 | B5: spicy_sriracharrow | C5: Sriracharrow | D5: Sriracha Sparrow | E5: Meal | F5: Spicy | G5: No | H5: =IF(E5="Chef","Mythic",IF(G5="Yes","Rare",IF(OR(E5="Meal",E5="Spice",E5="Environment"),"Uncommon","Common"))) -> Uncommon | I5: 5 | J5: 4 | K5: Spicy | L5: 1 | M5: 0 | N5: =IF(E5="Meal",L5,M5) -> 1 | R5: Spicy Starter | S5: 2 | T5: data/cards.json
A6: 2 | B6: spicy_firecracker_shrimp | C6: Firecracker Shrimp | E6: Meal | F6: Spicy | G6: No | H6: =IF(E6="Chef","Mythic",IF(G6="Yes","Rare",IF(OR(E6="Meal",E6="Spice",E6="Environment"),"Uncommon","Common"))) -> Uncommon | I6: 7 | J6: 5 | K6: Spicy + Spicy | L6: 2 | M6: 0 | N6: =IF(E6="Meal",L6,M6) -> 2 | P6: When this attacks, deal 2 damage to one opposing card in Prep. | Q6: on_attack | R6: Spicy Starter | S6: 2 | T6: data/cards.json
A7: 3 | B7: spicy_vindaloo_beluga | C7: Vindaloo Beluga | E7: Meal | F7: Spicy | G7: Yes | H7: =IF(E7="Chef","Mythic",IF(G7="Yes","Rare",IF(OR(E7="Meal",E7="Spice",E7="Environment"),"Uncommon","Common"))) -> Rare | I7: 3 | J7: 3 | K7: Spicy | L7: 1 | M7: 0 | N7: =IF(E7="Meal",L7,M7) -> 1 | P7: Sacrifice this meal: deal 4 damage to a target opposing Plated unit. | Q7: abilities | S7: 0 | T7: data/cards.json
A8: 4 | B8: spicy_hot_pot_panda | C8: Hot Pot Panda | E8: Meal | F8: Spicy | G8: Yes | H8: =IF(E8="Chef","Mythic",IF(G8="Yes","Rare",IF(OR(E8="Meal",E8="Spice",E8="Environment"),"Uncommon","Common"))) -> Rare | I8: 6 | J8: 6 | K8: Spicy + Spicy | L8: 2 | M8: 0 | N8: =IF(E8="Meal",L8,M8) -> 2 | P8: Whenever this is dealt damage, deal 1 damage to the opposing chef. | Q8: on_damaged | S8: 0 | T8: data/cards.json
A9: 5 | B9: spicy_buffalo_wings | C9: Buffalo Wings | D9: Buffalo | E9: Meal | F9: Spicy | G9: Yes | H9: =IF(E9="Chef","Mythic",IF(G9="Yes","Rare",IF(OR(E9="Meal",E9="Spice",E9="Environment"),"Uncommon","Common"))) -> Rare | I9: 9 | J9: 6 | K9: Spicy + Spicy + Spicy | L9: 3 | M9: 0 | N9: =IF(E9="Meal",L9,M9) -> 3 | P9: When served, deal 1 damage to all enemies. | Q9: on_play | R9: Spicy Starter | S9: 1 | T9: data/cards.json
A10: 6 | B10: hearty_dumpling_tortoise | C10: Dumpling-Backed Tortoise | E10: Meal | F10: Hearty | G10: No | H10: =IF(E10="Chef","Mythic",IF(G10="Yes","Rare",IF(OR(E10="Meal",E10="Spice",E10="Environment"),"Uncommon","Common"))) -> Uncommon | I10: 4 | J10: 5 | K10: Hearty | L10: 1 | M10: 0 | N10: =IF(E10="Meal",L10,M10) -> 1 | R10: Hearty Starter | S10: 2 | T10: data/cards.json
A11: 7 | B11: hearty_stewoose | C11: Stewoose | D11: Stew Moose | E11: Meal | F11: Hearty | G11: No | H11: =IF(E11="Chef","Mythic",IF(G11="Yes","Rare",IF(OR(E11="Meal",E11="Spice",E11="Environment"),"Uncommon","Common"))) -> Uncommon | I11: 4 | J11: 8 | K11: Hearty + Hearty | L11: 2 | M11: 0 | N11: =IF(E11="Meal",L11,M11) -> 2 | P11: When served, heal your chef for 2. | Q11: on_play | R11: Hearty Starter | S11: 2 | T11: data/cards.json
A12: 8 | B12: hearty_bison_burrito | C12: Bison Burrito | D12: Burrito Bison | E12: Meal | F12: Hearty | G12: Yes | H12: =IF(E12="Chef","Mythic",IF(G12="Yes","Rare",IF(OR(E12="Meal",E12="Spice",E12="Environment"),"Uncommon","Common"))) -> Rare | I12: 3 | J12: 3 | K12: Hearty | L12: 1 | M12: 0 | N12: =IF(E12="Meal",L12,M12) -> 1 | P12: While this is in Prep, your Plated units get +1/+1. | Q12: auras | S12: 0 | T12: data/cards.json
A13: 9 | B13: hearty_mastiff_potato | C13: Mastiff Potato | D13: Mastiff Mashed Potato | E13: Meal | F13: Hearty | G13: Yes | H13: =IF(E13="Chef","Mythic",IF(G13="Yes","Rare",IF(OR(E13="Meal",E13="Spice",E13="Environment"),"Uncommon","Common"))) -> Rare | I13: 4 | J13: 6 | K13: Hearty + Any | L13: 2 | M13: 0 | N13: =IF(E13="Meal",L13,M13) -> 2 | P13: The first time this moves from Prep to Plated, it gets +2/+2. | Q13: on_move_to_plated | S13: 0 | T13: data/cards.json
A14: 10 | B14: hearty_polar_pot_pie_bear | C14: Polar Pot Pie Bear | D14: Pot Pie Polar Bear | E14: Meal | F14: Hearty | G14: Yes | H14: =IF(E14="Chef","Mythic",IF(G14="Yes","Rare",IF(OR(E14="Meal",E14="Spice",E14="Environment"),"Uncommon","Common"))) -> Rare | I14: 8 | J14: 8 | K14: Hearty + Hearty + Hearty | L14: 3 | M14: 0 | N14: =IF(E14="Meal",L14,M14) -> 3 | P14: While Plated, once per turn heal 1 damage from each other friendly unit. | Q14: abilities | R14: Hearty Starter | S14: 1 | T14: data/cards.json
A15: 11 | B15: sweet_pup_tart | C15: Pup Tart | E15: Meal | F15: Sweet | G15: No | H15: =IF(E15="Chef","Mythic",IF(G15="Yes","Rare",IF(OR(E15="Meal",E15="Spice",E15="Environment"),"Uncommon","Common"))) -> Uncommon | I15: 4 | J15: 5 | K15: Sweet | L15: 1 | M15: 0 | N15: =IF(E15="Meal",L15,M15) -> 1 | R15: Sweet Starter | S15: 1 | T15: data/cards.json
A16: 12 | B16: sweet_strawberry_sharkcake | C16: Strawberry Sharkcake | D16: Shortcake Shark | E16: Meal | F16: Sweet | G16: No | H16: =IF(E16="Chef","Mythic",IF(G16="Yes","Rare",IF(OR(E16="Meal",E16="Spice",E16="Environment"),"Uncommon","Common"))) -> Uncommon | I16: 5 | J16: 6 | K16: Sweet + Sweet | L16: 2 | M16: 0 | N16: =IF(E16="Meal",L16,M16) -> 2 | P16: When served, draw 2 cards. | Q16: on_play | R16: Sweet Starter | S16: 2 | T16: data/cards.json
A17: 13 | B17: sweet_donutphin | C17: Donutphin | D17: Donut Dolphin | E17: Meal | F17: Sweet | G17: Yes | H17: =IF(E17="Chef","Mythic",IF(G17="Yes","Rare",IF(OR(E17="Meal",E17="Spice",E17="Environment"),"Uncommon","Common"))) -> Rare | I17: 3 | J17: 4 | K17: Sweet | L17: 1 | M17: 0 | N17: =IF(E17="Meal",L17,M17) -> 1 | P17: When this deals combat damage to the opposing chef, they cannot use a Chef next turn. | Q17: on_combat_damage_to_chef | S17: 0 | T17: data/cards.json
A18: 14 | B18: sweet_pandacake | C18: Pandacake | D18: Pancake Panda | E18: Meal | F18: Sweet | G18: Yes | H18: =IF(E18="Chef","Mythic",IF(G18="Yes","Rare",IF(OR(E18="Meal",E18="Spice",E18="Environment"),"Uncommon","Common"))) -> Rare | I18: 5 | J18: 6 | K18: Sweet + Sweet | L18: 2 | M18: 0 | N18: =IF(E18="Meal",L18,M18) -> 2 | P18: While this is in Prep, your other Plated units have +2 Health. | Q18: auras | S18: 0 | T18: data/cards.json
A19: 15 | B19: sweet_cinnamon_snail | C19: Cinnamon Snail | D19: Cinnamon Roll Snail | E19: Meal | F19: Sweet | G19: Yes | H19: =IF(E19="Chef","Mythic",IF(G19="Yes","Rare",IF(OR(E19="Meal",E19="Spice",E19="Environment"),"Uncommon","Common"))) -> Rare | I19: 4 | J19: 6 | K19: Sweet + Sweet | L19: 2 | M19: 0 | N19: =IF(E19="Meal",L19,M19) -> 2 | P19: While this is Plated, opposing Meals require 1 additional Ingredient and opposing healing is reduced by 2. | Q19: auras, opponent_healing_reduction | R19: Sweet Starter | S19: 2 | T19: data/cards.json
A20: 16 | B20: sweet_parfait_parrot | C20: Parfait Parrot | E20: Meal | F20: Sweet | G20: Yes | H20: =IF(E20="Chef","Mythic",IF(G20="Yes","Rare",IF(OR(E20="Meal",E20="Spice",E20="Environment"),"Uncommon","Common"))) -> Rare | I20: 4 | J20: 5 | K20: Sweet + Sweet | L20: 2 | M20: 0 | N20: =IF(E20="Meal",L20,M20) -> 2 | P20: At the end of your turn, if this is Plated, draw 1 card. | Q20: on_end_turn, end_turn_zone | S20: 0 | T20: data/cards.json
A21: 17 | B21: hearty_gravy_gazelle | C21: Gravy Gazelle | E21: Meal | F21: Hearty | G21: No | H21: =IF(E21="Chef","Mythic",IF(G21="Yes","Rare",IF(OR(E21="Meal",E21="Spice",E21="Environment"),"Uncommon","Common"))) -> Uncommon | I21: 3 | J21: 5 | K21: Hearty | L21: 1 | M21: 0 | N21: =IF(E21="Meal",L21,M21) -> 1 | P21: While Plated, once per turn give a friendly Plated unit +1/+1. | Q21: abilities | S21: 0 | T21: data/cards.json
A22: 18 | B22: fresh_harvest_hydra | C22: Harvest Hydra | E22: Meal | F22: Fresh | G22: Yes | H22: =IF(E22="Chef","Mythic",IF(G22="Yes","Rare",IF(OR(E22="Meal",E22="Spice",E22="Environment"),"Uncommon","Common"))) -> Rare | I22: 2 | J22: 2 | K22: Fresh | L22: 1 | M22: 0 | N22: =IF(E22="Meal",L22,M22) -> 1 | P22: To serve this, also sacrifice a Fresh Meal. When served, sacrifice all your other units; this gains their combined Attack and maximum Health, including the units used to serve it. | Q22: required_meal_archetype, on_play | R22: Fresh Starter | S22: 1 | T22: data/cards.json
A23: 19 | B23: fresh_garden_gorilla | C23: Garden Gorilla | E23: Meal | F23: Fresh | G23: No | H23: =IF(E23="Chef","Mythic",IF(G23="Yes","Rare",IF(OR(E23="Meal",E23="Spice",E23="Environment"),"Uncommon","Common"))) -> Uncommon | I23: 3 | J23: 5 | K23: Fresh + Fresh | L23: 2 | M23: 0 | N23: =IF(E23="Meal",L23,M23) -> 2 | P23: This gets +2 Attack for each other Fresh unit in your Prep area. | Q23: self_attack_per_friendly_prep_archetype, count_archetype | R23: Fresh Starter | S23: 2 | T23: data/cards.json
A24: 20 | B24: fresh_saladmander | C24: Saladmander | D24: Salad Salamander | E24: Meal | F24: Fresh | G24: No | H24: =IF(E24="Chef","Mythic",IF(G24="Yes","Rare",IF(OR(E24="Meal",E24="Spice",E24="Environment"),"Uncommon","Common"))) -> Uncommon | I24: 4 | J24: 5 | K24: Fresh | L24: 1 | M24: 0 | N24: =IF(E24="Meal",L24,M24) -> 1 | R24: Fresh Starter | S24: 2 | T24: data/cards.json
A25: 21 | B25: spicy_pepper_pike | C25: Pepper Pike | E25: Meal | F25: Spicy | G25: No | H25: =IF(E25="Chef","Mythic",IF(G25="Yes","Rare",IF(OR(E25="Meal",E25="Spice",E25="Environment"),"Uncommon","Common"))) -> Uncommon | I25: 4 | J25: 3 | K25: Spicy | L25: 1 | M25: 0 | N25: =IF(E25="Meal",L25,M25) -> 1 | P25: While Plated, once per turn deal 1 damage to an opposing Meal. | Q25: abilities | S25: 0 | T25: data/cards.json
A26: 22 | B26: hearty_meatloaf_mole | C26: Meatloaf Mole | E26: Meal | F26: Hearty | G26: Yes | H26: =IF(E26="Chef","Mythic",IF(G26="Yes","Rare",IF(OR(E26="Meal",E26="Spice",E26="Environment"),"Uncommon","Common"))) -> Rare | I26: 5 | J26: 6 | K26: Hearty + Hearty | L26: 2 | M26: 0 | N26: =IF(E26="Meal",L26,M26) -> 2 | P26: When this KOs an opposing unit, heal 2 damage from this. | Q26: on_ko_enemy | S26: 0 | T26: data/cards.json
A27: 23 | B27: hearty_broth_buffalo | C27: Broth Buffalo | E27: Meal | F27: Hearty | G27: Yes | H27: =IF(E27="Chef","Mythic",IF(G27="Yes","Rare",IF(OR(E27="Meal",E27="Spice",E27="Environment"),"Uncommon","Common"))) -> Rare | I27: 4 | J27: 7 | K27: Hearty + Hearty | L27: 2 | M27: 0 | N27: =IF(E27="Meal",L27,M27) -> 2 | P27: While Plated, once per turn heal 2 damage from a friendly unit. | Q27: abilities | S27: 0 | T27: data/cards.json
A28: 24 | B28: funky_remix_raccoon | C28: Remix Raccoon | E28: Meal | F28: Funky | G28: Yes | H28: =IF(E28="Chef","Mythic",IF(G28="Yes","Rare",IF(OR(E28="Meal",E28="Spice",E28="Environment"),"Uncommon","Common"))) -> Rare | I28: 4 | J28: 6 | K28: Funky + Funky + Funky | L28: 3 | M28: 0 | N28: =IF(E28="Meal",L28,M28) -> 3 | P28: Once per turn, copy the activated ability of another unit in your Prep area and pay its costs. | Q28: abilities | R28: Funky Starter | S28: 2 | T28: data/cards.json
A29: 25 | B29: funky_leftover_lynx | C29: Leftover Lynx | E29: Meal | F29: Funky | G29: No | H29: =IF(E29="Chef","Mythic",IF(G29="Yes","Rare",IF(OR(E29="Meal",E29="Spice",E29="Environment"),"Uncommon","Common"))) -> Uncommon | I29: 4 | J29: 6 | K29: Funky + Funky | L29: 2 | M29: 0 | N29: =IF(E29="Meal",L29,M29) -> 2 | P29: When served, return a unit from your discard pile to your hand. | Q29: on_play | R29: Funky Starter | S29: 2 | T29: data/cards.json
A30: 26 | B30: sweet_bottomless_trifle_tern | C30: Bottomless Trifle Tern | E30: Meal | F30: Sweet | G30: Yes | H30: =IF(E30="Chef","Mythic",IF(G30="Yes","Rare",IF(OR(E30="Meal",E30="Spice",E30="Environment"),"Uncommon","Common"))) -> Rare | I30: 4 | J30: 5 | K30: Sweet | L30: 1 | M30: 0 | N30: =IF(E30="Meal",L30,M30) -> 1 | P30: To serve this, also sacrifice a Sweet Meal. The first time this attacks each turn, draw until you have 6 cards. | Q30: required_meal_archetype, on_attack | S30: 0 | T30: data/cards.json
A31: 27 | B31: sweet_pudding_puma | C31: Pudding Puma | E31: Meal | F31: Sweet | G31: Yes | H31: =IF(E31="Chef","Mythic",IF(G31="Yes","Rare",IF(OR(E31="Meal",E31="Spice",E31="Environment"),"Uncommon","Common"))) -> Rare | I31: 3 | J31: 4 | K31: Sweet + Sweet | L31: 2 | M31: 0 | N31: =IF(E31="Meal",L31,M31) -> 2 | P31: This can attack while in Prep. | Q31: can_attack_from_prep | S31: 0 | T31: data/cards.json
A32: 28 | B32: funky_trap_jam_tapir | C32: Trap Jam Tapir | E32: Meal | F32: Funky | G32: Yes | H32: =IF(E32="Chef","Mythic",IF(G32="Yes","Rare",IF(OR(E32="Meal",E32="Spice",E32="Environment"),"Uncommon","Common"))) -> Rare | I32: 3 | J32: 4 | K32: Funky | L32: 1 | M32: 0 | N32: =IF(E32="Meal",L32,M32) -> 1 | P32: While Plated, once per turn negate an opposing Hand Trap. | Q32: hand_trap_guard, hand_trap_guard_zone | R32: Funky Starter | S32: 2 | T32: data/cards.json
A33: 29 | B33: spicy_hot_honey_bee | C33: Hot Honey Bee | E33: Ingredient | F33: Spicy | G33: No | H33: =IF(E33="Chef","Mythic",IF(G33="Yes","Rare",IF(OR(E33="Meal",E33="Spice",E33="Environment"),"Uncommon","Common"))) -> Common | I33: 1 | J33: 1 | K33: Spicy | L33: 0 | M33: 0 | N33: =IF(E33="Meal",L33,M33) -> 0 | P33: When played, deal 1 damage to the opposing chef. | Q33: on_play | R33: Spicy Starter | S33: 3 | T33: data/cards.json
A34: 30 | B34: spicy_jalapeno_panther | C34: Jalapeño Panther | E34: Ingredient | F34: Spicy | G34: No | H34: =IF(E34="Chef","Mythic",IF(G34="Yes","Rare",IF(OR(E34="Meal",E34="Spice",E34="Environment"),"Uncommon","Common"))) -> Common | I34: 2 | J34: 3 | K34: Spicy | L34: 0 | M34: 0 | N34: =IF(E34="Meal",L34,M34) -> 0 | R34: Spicy Starter | S34: 2 | T34: data/cards.json
A35: 31 | B35: spicy_red_pepper_panda | C35: Red Pepper Panda | E35: Ingredient | F35: Spicy | G35: No | H35: =IF(E35="Chef","Mythic",IF(G35="Yes","Rare",IF(OR(E35="Meal",E35="Spice",E35="Environment"),"Uncommon","Common"))) -> Common | I35: 1 | J35: 2 | K35: Spicy | L35: 0 | M35: 0 | N35: =IF(E35="Meal",L35,M35) -> 0 | O35: Stalwart | P35: Stalwart — this card can attack the opposing chef even while they control Plated cards. | R35: Spicy Starter | S35: 3 | T35: data/cards.json
A36: 32 | B36: spicy_wasabi_wasp | C36: Wastabi | D36: Wasabi Wasp | E36: Ingredient | F36: Spicy | G36: Yes | H36: =IF(E36="Chef","Mythic",IF(G36="Yes","Rare",IF(OR(E36="Meal",E36="Spice",E36="Environment"),"Uncommon","Common"))) -> Rare | I36: 2 | J36: 1 | K36: Spicy | L36: 0 | M36: 0 | N36: =IF(E36="Meal",L36,M36) -> 0 | P36: When played, deal 1 damage to all opposing Plated units. | Q36: on_play | R36: Spicy Starter | S36: 2 | T36: data/cards.json
A37: 33 | B37: spicy_jalapeno_jackal | C37: Jakapeno | D37: Jalapeño Jackal | E37: Ingredient | F37: Spicy | G37: No | H37: =IF(E37="Chef","Mythic",IF(G37="Yes","Rare",IF(OR(E37="Meal",E37="Spice",E37="Environment"),"Uncommon","Common"))) -> Common | I37: 1 | J37: 1 | K37: Spicy | L37: 0 | M37: 0 | N37: =IF(E37="Meal",L37,M37) -> 0 | P37: Sacrifice this: search your deck for a Spicy card. | Q37: abilities | R37: Spicy Starter | S37: 1 | T37: data/cards.json
A38: 34 | B38: spicy_peppercorn_porcupine | C38: Peppercupine | D38: Peppercorn Porcupine | E38: Ingredient | F38: Spicy | G38: Yes | H38: =IF(E38="Chef","Mythic",IF(G38="Yes","Rare",IF(OR(E38="Meal",E38="Spice",E38="Environment"),"Uncommon","Common"))) -> Rare | I38: 2 | J38: 1 | K38: Spicy | L38: 0 | M38: 0 | N38: =IF(E38="Meal",L38,M38) -> 0 | P38: When played, search your deck for a Spicy meal. | Q38: on_play | S38: 0 | T38: data/cards.json
A39: 35 | B39: spicy_habanero_hare | C39: Harebanero | D39: Habanero Hare | E39: Ingredient | F39: Spicy | G39: No | H39: =IF(E39="Chef","Mythic",IF(G39="Yes","Rare",IF(OR(E39="Meal",E39="Spice",E39="Environment"),"Uncommon","Common"))) -> Common | I39: 2 | J39: 1 | K39: Spicy | L39: 0 | M39: 0 | N39: =IF(E39="Meal",L39,M39) -> 0 | P39: When sacrificed, deal 2 damage to a random opposing card in Prep. | Q39: on_sacrifice | S39: 0 | T39: data/cards.json
A40: 36 | B40: spicy_ghost_pepper_python | C40: Ghost Pepython | D40: Ghost Pepper Python | E40: Ingredient | F40: Spicy | G40: Yes | H40: =IF(E40="Chef","Mythic",IF(G40="Yes","Rare",IF(OR(E40="Meal",E40="Spice",E40="Environment"),"Uncommon","Common"))) -> Rare | I40: 2 | J40: 1 | K40: Spicy | L40: 0 | M40: 0 | N40: =IF(E40="Meal",L40,M40) -> 0 | P40: When played, discard your hand. If you discarded at least one card this way, draw 3. | Q40: on_play | S40: 0 | T40: data/cards.json
A41: 37 | B41: spicy_chili_cicada | C41: Chili Cicada | E41: Ingredient | F41: Spicy | G41: Yes | H41: =IF(E41="Chef","Mythic",IF(G41="Yes","Rare",IF(OR(E41="Meal",E41="Spice",E41="Environment"),"Uncommon","Common"))) -> Rare | I41: 1 | J41: 1 | K41: Spicy | L41: 0 | M41: 0 | N41: =IF(E41="Meal",L41,M41) -> 0 | P41: When this is KO'd, deal 3 damage to an opposing unit. | Q41: on_ko | S41: 0 | T41: data/cards.json
...

Sheet Starter Decks
A1: Starter Deck Coverage
A2: One row per card entry in each implemented 30-card starter deck.
A4: Deck ID | B4: Deck Name | C4: Archetype | D4: Card ID | E4: Card Name | F4: Card Type | G4: Count
A5: spicy_test_kitchen | B5: Spicy Starter | C5: Spicy | D5: spicy_sriracharrow | E5: Sriracharrow | F5: Meal | G5: 2
A6: spicy_test_kitchen | B6: Spicy Starter | C6: Spicy | D6: spicy_firecracker_shrimp | E6: Firecracker Shrimp | F6: Meal | G6: 2
A7: spicy_test_kitchen | B7: Spicy Starter | C7: Spicy | D7: spicy_buffalo_wings | E7: Buffalo Wings | F7: Meal | G7: 1
A8: spicy_test_kitchen | B8: Spicy Starter | C8: Spicy | D8: spicy_hot_honey_bee | E8: Hot Honey Bee | F8: Ingredient | G8: 3
A9: spicy_test_kitchen | B9: Spicy Starter | C9: Spicy | D9: spicy_jalapeno_panther | E9: Jalapeño Panther | F9: Ingredient | G9: 2
A10: spicy_test_kitchen | B10: Spicy Starter | C10: Spicy | D10: spicy_red_pepper_panda | E10: Red Pepper Panda | F10: Ingredient | G10: 3
A11: spicy_test_kitchen | B11: Spicy Starter | C11: Spicy | D11: spicy_wasabi_wasp | E11: Wastabi | F11: Ingredient | G11: 2
A12: spicy_test_kitchen | B12: Spicy Starter | C12: Spicy | D12: spicy_jalapeno_jackal | E12: Jakapeno | F12: Ingredient | G12: 1
A13: spicy_test_kitchen | B13: Spicy Starter | C13: Spicy | D13: item_spicy_shopping_list | E13: Spicy Shopping List | F13: Tool | G13: 1
A14: spicy_test_kitchen | B14: Spicy Starter | C14: Spicy | D14: item_recipe_prep | E14: Recipe Prep | F14: Tool | G14: 3
A15: spicy_test_kitchen | B15: Spicy Starter | C15: Spicy | D15: item_tool_drawer | E15: Tool Drawer | F15: Tool | G15: 2
A16: spicy_test_kitchen | B16: Spicy Starter | C16: Spicy | D16: item_wooden_spoon | E16: Wooden Spoon | F16: Tool | G16: 3
... A75: funky_test_kitchen | B75: Funky Starter | C75: Funky | D75: chef_mary | E75: Chef Mary | F75: Chef | G75: 2
